(dp1
S'output'
p2
S"<type 'exceptions.KeyError'> 'posts_id'"
p3
sS'layer'
p4
S'/mnt/c/Users/Ziming/Desktop/UCSC-Fall-18/CMPS183/said-it/applications/init/controllers/api.py'
p5
sS'code'
p6
S'<code object <module> at 0x7fc14c131db0, file "/mnt/c/Users/Ziming/Desktop/UCSC-Fall-18/CMPS183/said-it/applications/init/controllers/api.py", line 1>'
p7
sS'snapshot'
p8
(dp9
sS'traceback'
p10
S'Traceback (most recent call last):\n  File "/mnt/c/Users/Ziming/Desktop/UCSC-Fall-18/CMPS183/said-it/gluon/restricted.py", line 219, in restricted\n    exec(ccode, environment)\n  File "/mnt/c/Users/Ziming/Desktop/UCSC-Fall-18/CMPS183/said-it/applications/init/controllers/api.py", line 32, in <module>\n  File "/mnt/c/Users/Ziming/Desktop/UCSC-Fall-18/CMPS183/said-it/gluon/globals.py", line 421, in <lambda>\n    self._caller = lambda f: f()\n  File "/mnt/c/Users/Ziming/Desktop/UCSC-Fall-18/CMPS183/said-it/applications/init/controllers/api.py", line 28, in edit_post\n    posts_content=request.vars.posts_content\n  File "/mnt/c/Users/Ziming/Desktop/UCSC-Fall-18/CMPS183/said-it/gluon/packages/dal/pydal/objects.py", line 822, in update_or_insert\n    record = self(**values)\n  File "/mnt/c/Users/Ziming/Desktop/UCSC-Fall-18/CMPS183/said-it/gluon/packages/dal/pydal/objects.py", line 592, in __call__\n    self[k] == v for k, v in iteritems(kwargs)])\n  File "/mnt/c/Users/Ziming/Desktop/UCSC-Fall-18/CMPS183/said-it/gluon/packages/dal/pydal/objects.py", line 559, in __getitem__\n    raise KeyError(key)\nKeyError: \'posts_id\'\n'
p11
s.